Workbook

Sheet MAIN (Anterior)
D2: PMS LIST - ELECTROMECHANICAL ENGINEERING | P2: TOTAL DOCUMENTS
P3: =SUM(Q7,Q8,Q17,Q18,Q27,Q32,Q40,Q36,Q23,Q22,Q12,Q13) -> 6616
C5: Instrução de manutenção /Maintenance instruction
C6: Electrical Maintenance Instructions | H6: Mechanical Maintenance Instructions | L6: Normative and Managerial Maintenance Instructions | Q6: TOTAL
B7: Total Instruções CTGBr "Por" | C7: =COUNTIFS(IM!G5:G161,"x",IM!B5:B161,"Instruções Manutenção Elétrica") -> 29 | H7: =COUNTIFS(IM!G5:G161,"x",IM!B5:B161,"Instruções Manutenção Mecânica") -> 29 | L7: =COUNTIFS(IM!G5:G161,"x",IM!B5:B161,"Instruções Manutenção Normativas e Gerenciais") -> 32 | Q7: =SUM(C7:P7) -> 90
B8: Total Instructions CTGBr "Eng" | C8: =COUNTIFS(IM!H5:H161,"x",IM!B5:B161,"Instruções Manutenção Elétrica") -> 12 | H8: =COUNTIFS(IM!H5:H161,"x",IM!B5:B161,"Instruções Manutenção Mecânica") -> 8 | L8: =COUNTIFS(IM!H5:H161,"x",IM!B5:B161,"Instruções Manutenção Normativas e Gerenciais") -> 20 | Q8: =SUM(C8:P8) -> 40
C10: Instrução de operaçaõ/Operating instruction
C11: Instruções de operação local | J11: Instruções de operação sistêmica | Q11: TOTAL
B12: Total Instruções CTGBr "Por" | C12: =COUNTIFS(IO!F5:F276,"X",IO!B5:B276,"Instruções de operação local") -> 8 | J12: =COUNTIFS(IO!F5:F276,"X",IO!B5:B276,"Instruções de operação sistêmica") -> 76 | Q12: =SUM(C12:P12) -> 84
B13: Total Instructions CTGBr "Eng" | C13: =COUNTIFS(IO!G5:G276,"X",IO!B5:B276,"Instruções de operação local") -> 6 | J13: =COUNTIFS(IO!G5:G276,"X",IO!B5:B276,"Instruções de operação sistêmica") -> 63 | Q13: =SUM(C13:P13) -> 69
C15: Guia de manutenção/Maintenance guide
C16: JUR | D16: CHV | E16: SAG | F16: CN1 | G16: CN2 | H16: CPV | I16: TAQ | J16: ROS | K16: PLM | L16: RET | M16: ILS | N16: JUP | O16: STO | P16: GAR | Q16: TOTAL
B17: Total Guias CTGBr "Por" | C17: =COUNTIFS(GM!$H$5:$H$1014,"X",GM!$C$5:$C$1014,"JUR") -> 50 | D17: =COUNTIFS(GM!$H$5:$H$1014,"X",GM!$C$5:$C$1014,"chv") -> 49 | E17: =COUNTIFS(GM!$H$5:$H$1014,"X",GM!$C$5:$C$1014,"sag") -> 45 | F17: =COUNTIFS(GM!$H$5:$H$1014,"X",GM!$C$5:$C$1014,"cn1") -> 49 | G17: =COUNTIFS(GM!$H$5:$H$1014,"X",GM!$C$5:$C$1014,"cn2") -> 49 | H17: =COUNTIFS(GM!$H$5:$H$1014,"X",GM!$C$5:$C$1014,"cpv") -> 48 | I17: =COUNTIFS(GM!$H$5:$H$1014,"X",GM!$C$5:$C$1014,"taq") -> 48 | J17: =COUNTIFS(GM!$H$5:$H$1014,"X",GM!$C$5:$C$1014,"ROS") -> 49 | K17: =COUNTIFS(GM!$H$5:$H$1014,"X",GM!$C$5:$C$1014,"PLM") -> 41 | L17: =COUNTIFS(GM!$H$5:$H$1014,"X",GM!$C$5:$C$1014,"RET") -> 41 | M17: =COUNTIFS(GM!$H$5:$H$1014,"X",GM!$C$5:$C$1014,"ILS") -> 62 | N17: =COUNTIFS(GM!$H$5:$H$1014,"X",GM!$C$5:$C$1014,"JUP") -> 64 | O17: =COUNTIFS(GM!$H$5:$H$1014,"X",GM!$C$5:$C$1014,"STO") -> 48 | P17: =COUNTIFS(GM!$H$5:$H$1014,"X",GM!$C$5:$C$1014,"GAR") -> 58 | Q17: =SUM(C17:P17) -> 701
B18: Total Guides CTGBr "Eng" | C18: =COUNTIFS(GM!$I$5:$I$1014,"X",GM!$C$5:$C$1014,"JUR") -> 47 | D18: =COUNTIFS(GM!$I$5:$I$1014,"X",GM!$C$5:$C$1014,"CHV") -> 46 | E18: =COUNTIFS(GM!$I$5:$I$1014,"X",GM!$C$5:$C$1014,"SAG") -> 42 | F18: =COUNTIFS(GM!$I$5:$I$1014,"X",GM!$C$5:$C$1014,"CN1") -> 45 | G18: =COUNTIFS(GM!$I$5:$I$1014,"X",GM!$C$5:$C$1014,"CN2") -> 45 | H18: =COUNTIFS(GM!$I$5:$I$1014,"X",GM!$C$5:$C$1014,"CPV") -> 44 | I18: =COUNTIFS(GM!$I$5:$I$1014,"X",GM!$C$5:$C$1014,"TAQ") -> 44 | J18: =COUNTIFS(GM!$I$5:$I$1014,"X",GM!$C$5:$C$1014,"ROS") -> 45 | K18: =COUNTIFS(GM!$I$5:$I$1014,"X",GM!$C$5:$C$1014,"PLM") -> 38 | L18: =COUNTIFS(GM!$I$5:$I$1014,"X",GM!$C$5:$C$1014,"RET") -> 38 | M18: =COUNTIFS(GM!$I$5:$I$1014,"X",GM!$C$5:$C$1014,"ILS") -> 58 | N18: =COUNTIFS(GM!$I$5:$I$1014,"X",GM!$C$5:$C$1014,"JUP") -> 60 | O18: =COUNTIFS(GM!$I$5:$I$1014,"X",GM!$C$5:$C$1014,"STO") -> 44 | P18: =COUNTIFS(GM!$I$5:$I$1014,"X",GM!$C$5:$C$1014,"GAR") -> 52 | Q18: =SUM(C18:P18) -> 648
C20: Guia de operação/Operation guide
C21: JUR | D21: CHV | E21: SAG | F21: CN1 | G21: CN2 | H21: CPV | I21: TAQ | J21: ROS | K21: PLM | L21: RET | M21: ILS | N21: JUP | O21: STO | P21: GAR | Q21: TOTAL
B22: Total Guias CTGBr "Por" | C22: =COUNTIFS(GO!G16:G457,"X",GO!C16:C457,"JUR") -> 0 | D22: =COUNTIFS(GO!G16:G457,"X",GO!C16:C457,"CHV") -> 5 | E22: =COUNTIFS(GO!G16:G457,"X",GO!C16:C457,"SAG") -> 8 | F22: =COUNTIFS(GO!G16:G457,"X",GO!C16:C457,"CN1") -> 7 | G22: =COUNTIFS(GO!G16:G457,"X",GO!C16:C457,"CN2") -> 7 | H22: =COUNTIFS(GO!G16:G457,"X",GO!C16:C457,"CPV") -> 8 | I22: =COUNTIFS(GO!G16:G457,"X",GO!C16:C457,"TAQ") -> 8 | J22: =COUNTIFS(GO!G16:G457,"X",GO!C16:C457,"ROS") -> 9 | K22: =COUNTIFS(GO!G16:G457,"X",GO!C16:C457,"PLM") -> 8 | L22: =COUNTIFS(GO!G16:G457,"X",GO!C16:C457,"RET") -> 8 | M22: =COUNTIFS(GO!G16:G457,"X",GO!C16:C457,"ILS") -> 73 | N22: =COUNTIFS(GO!G16:G457,"X",GO!C16:C457,"JUP") -> 41 | O22: =COUNTIFS(GO!G16:G457,"X",GO!C16:C457,"STO") -> 9 | P22: =COUNTIFS(GO!G16:G457,"X",GO!C16:C457,"GAR") -> 4 | Q22: =SUM(C22:P22) -> 195
B23: Total Guides CTGBr "Eng" | C23: =COUNTIFS(GO!H16:H457,"X",GO!C16:C457,"JUR") -> 0 | D23: =COUNTIFS(GO!H16:H457,"X",GO!C16:C457,"CHV") -> 2 | E23: =COUNTIFS(GO!H16:H457,"X",GO!C16:C457,"SAG") -> 4 | F23: =COUNTIFS(GO!H16:H457,"X",GO!C16:C457,"CN1") -> 4 | G23: =COUNTIFS(GO!H16:H457,"X",GO!C16:C457,"CN2") -> 4 | H23: =COUNTIFS(GO!H16:H457,"X",GO!C16:C457,"CPV") -> 3 | I23: =COUNTIFS(GO!H16:H457,"X",GO!C16:C457,"TAQ") -> 3 | J23: =COUNTIFS(GO!H16:H457,"X",GO!C16:C457,"ROS") -> 4 | K23: =COUNTIFS(GO!H16:H457,"X",GO!C16:C457,"PLM") -> 4 | L23: =COUNTIFS(GO!H16:H457,"X",GO!C16:C457,"RET") -> 4 | M23: =COUNTIFS(GO!H16:H457,"X",GO!C16:C457,"ILS") -> 22 | N23: =COUNTIFS(GO!H16:H457,"X",GO!C16:C457,"JUP") -> 3 | O23: =COUNTIFS(GO!H16:H457,"X",GO!C16:C457,"STO") -> 9 | P23: =COUNTIFS(GO!H16:H457,"X",GO!C16:C457,"GAR") -> 4 | Q23: =SUM(C23:P23) -> 70
C25: Protocolo/Protocol
C26: JUR | D26: CHV | E26: SAG | F26: CN1 | G26: CN2 | H26: CPV | I26: TAQ | J26: ROS | K26: PLM | L26: RET | M26: ILS | N26: JUP | O26: STO | P26: GAR | Q26: TOTAL
B27: Total Protocolos CTGBr | C27: =COUNTIFS(PR!F5:F4771,"x",PR!A5:A4771,"JUR") -> 298 | D27: =COUNTIFS(PR!F5:F4771,"x",PR!A5:A4771,"CHV") -> 290 | E27: =COUNTIFS(PR!F5:F4771,"x",PR!A5:A4771,"SAG") -> 281 | F27: =COUNTIFS(PR!F5:F4771,"x",PR!A5:A4771,"CN1") -> 296 | G27: =COUNTIFS(PR!F5:F4771,"x",PR!A5:A4771,"CN2") -> 293 | H27: =COUNTIFS(PR!F5:F4771,"x",PR!A5:A4771,"CPV") -> 286 | I27: =COUNTIFS(PR!F5:F4771,"x",PR!A5:A4771,"TAQ") -> 311 | J27: =COUNTIFS(PR!F5:F4771,"x",PR!A5:A4771,"ROS") -> 308 | K27: =COUNTIFS(PR!F5:F4771,"x",PR!A5:A4771,"PLM") -> 252 | L27: =COUNTIFS(PR!F5:F4771,"x",PR!A5:A4771,"RET") -> 252 | M27: =COUNTIFS(PR!F5:F4771,"x",PR!A5:A4771,"ILS") -> 315 | N27: =COUNTIFS(PR!F5:F4771,"x",PR!A5:A4771,"JUP") -> 324 | O27: =COUNTIFS(PR!F5:F4771,"x",PR!A5:A4771,"STO") -> 273 | P27: =COUNTIFS(PR!F5:F4771,"x",PR!A5:A4771,"GAR") -> 306 | Q27: =SUM(C27:P27) -> 4085
B28: Total Protocols CTGBr "Eng" | C28: =COUNTIFS(PR!G5:G4771,"x",PR!A5:A4771,"JUR") -> 8 | D28: =COUNTIFS(PR!G5:G4771,"x",PR!A5:A4771,"CHV") -> 8 | E28: =COUNTIFS(PR!G5:G4771,"x",PR!A5:A4771,"SAG") -> 7 | F28: =COUNTIFS(PR!G5:G4771,"x",PR!A5:A4771,"CN1") -> 8 | G28: =COUNTIFS(PR!G5:G4771,"x",PR!A5:A4771,"CN2") -> 8 | H28: =COUNTIFS(PR!G5:G4771,"x",PR!A5:A4771,"CPV") -> 8 | I28: =COUNTIFS(PR!G5:G4771,"x",PR!A5:A4771,"TAQ") -> 8 | J28: =COUNTIFS(PR!G5:G4771,"x",PR!A5:A4771,"ROS") -> 8 | K28: =COUNTIFS(PR!G5:G4771,"x",PR!A5:A4771,"PLM") -> 8 | L28: =COUNTIFS(PR!G5:G4771,"x",PR!A5:A4771,"RET") -> 8 | M28: =COUNTIFS(PR!G5:G4771,"x",PR!A5:A4771,"ILS") -> 10 | N28: =COUNTIFS(PR!G5:G4771,"x",PR!A5:A4771,"JUP") -> 8 | O28: =COUNTIFS(PR!G5:G4771,"x",PR!A5:A4771,"STO") -> 8 | P28: =COUNTIFS(PR!G5:G4771,"x",PR!A5:A4771,"GAR") -> 8 | Q28: =SUM(C28:P28) -> 113
C30: Manual de manutenção/Maintenance manual
C31: JUR | D31: CHV | E31: SAG | F31: CN1 | G31: CN2 | H31: CPV | I31: TAQ | J31: ROS | K31: PLM | L31: RET | M31: ILS | N31: JUP | O31: STO | P31: GAR | Q31: TOTAL
B32: Total Manuals CTGBr | C32: =COUNTIFS(MM!M7:M642,"Publicado",MM!C7:C642,"JUR") -> 21 | D32: =COUNTIFS(MM!M7:M642,"Publicado",MM!C7:C642,"CHV") -> 19 | E32: =COUNTIFS(MM!M7:M642,"Publicado",MM!C7:C642,"SAG") -> 25 | F32: =COUNTIFS(MM!M7:M642,"Publicado",MM!C7:C642,"CN1") -> 30 | G32: =COUNTIFS(MM!M7:M642,"Publicado",MM!C7:C642,"CN2") -> 33 | H32: =COUNTIFS(MM!M7:M642,"Publicado",MM!C7:C642,"CPV") -> 31 | I32: =COUNTIFS(MM!M7:M642,"Publicado",MM!C7:C642,"TAQ") -> 20 | J32: =COUNTIFS(MM!M7:M642,"Publicado",MM!C7:C642,"ROS") -> 28 | K32: =COUNTIFS(MM!M7:M642,"Publicado",MM!C7:C642,"PLM") -> 16 | L32: =COUNTIFS(MM!M7:M642,"Publicado",MM!C7:C642,"RET") -> 15 | M32: =COUNTIFS(MM!M7:M642,"Publicado",MM!C7:C642,"ILS") -> 119 | N32: =COUNTIFS(MM!M7:M642,"Publicado",MM!C7:C642,"JUP") -> 43 | O32: =COUNTIFS(MM!M7:M642,"Publicado",MM!C7:C642,"STO") -> 4 | P32: =COUNTIFS(MM!M7:M642,"Publicado",MM!C7:C642,"GAR") -> 38 | Q32: =SUM(C32:P32) -> 442
C34: Manual de operação/Operation Manual
C35: JUR | D35: CHV | E35: SAG | F35: CN1 | G35: CN2 | H35: CPV | I35: TAQ | J35: ROS | K35: PLM | L35: RET | M35: ILS | N35: JUP | O35: STO | P35: GAR | Q35: TOTAL
B36: Total Manuals CTGBr | C36: =COUNTIFS(MO!K110:K659,"Publicado",MO!C110:C659,"JUR") -> 0 | D36: =COUNTIFS(MO!K110:K659,"Publicado",MO!C110:C659,"CHV") -> 0 | E36: =COUNTIFS(MO!K110:K659,"Publicado",MO!C110:C659,"SAG") -> 0 | F36: =COUNTIFS(MO!K110:K659,"Publicado",MO!C110:C659,"CN1") -> 0 | G36: =COUNTIFS(MO!K110:K659,"Publicado",MO!C110:C659,"CN2") -> 0 | H36: =COUNTIFS(MO!K110:K659,"Publicado",MO!C110:C659,"CPV") -> 16 | I36: =COUNTIFS(MO!K110:K659,"Publicado",MO!C110:C659,"TAQ") -> 21 | J36: =COUNTIFS(MO!K110:K659,"Publicado",MO!C110:C659,"ROS") -> 19 | K36: =COUNTIFS(MO!K110:K659,"Publicado",MO!C110:C659,"PLM") -> 25 | L36: =COUNTIFS(MO!K110:K659,"Publicado",MO!C110:C659,"RET") -> 25 | M36: =COUNTIFS(MO!K110:K659,"Publicado",MO!C110:C659,"ILS") -> 11 | N36: =COUNTIFS(MO!K110:K659,"Publicado",MO!C110:C659,"JUP") -> 27 | O36: =COUNTIFS(MO!K110:K659,"Publicado",MO!C110:C659,"STO") -> 10 | P36: =COUNTIFS(MO!K110:K659,"Publicado",MO!C110:C659,"GAR") -> 0 | Q36: =SUM(C36:P36) -> 154
C38: Política/Politic
C39: Políticas "Por" | J39: Politics "Eng" | Q39: TOTAL
B40: Total Politics CTGBr | C40: =COUNTIFS(POL!E5:E83,"X") -> 19 | J40: =COUNTIFS(POL!F5:F83,"X") -> 19 | Q40: =SUM(C40:P40) -> 38

Sheet MAIN
D2: PMS LIST - ELECTROMECHANICAL ENGINEERING | P2: TOTAL DOCUMENTS
P3: =SUM(U7,U17,U32,U36,U22,U12,C41) -> 1894
C5: Instrução de manutenção /Maintenance instruction
C6: Electrical Maintenance Instructions | H6: Mechanical Maintenance Instructions | L6: Normative and Managerial Maintenance Instructions | U6: TOTAL
B7: Total Instruções CTGBr "Por" | C7: =COUNTIFS(IM!G5:G199,"x",IM!B5:B199,"Instruções Manutenção Elétrica") -> 29 | H7: =COUNTIFS(IM!G5:G199,"x",IM!B5:B199,"Instruções Manutenção Mecânica") -> 29 | L7: =COUNTIFS(IM!G5:G199,"x",IM!B5:B199,"Instruções Manutenção Normativas e Gerenciais") -> 32 | U7: =SUM(C7:P7) -> 90 | V7: =U7-U8 -> 50
B8: Total Instructions CTGBr "Eng" | C8: =COUNTIFS(IM!H5:H199,"x",IM!B5:B199,"Instruções Manutenção Elétrica") -> 12 | H8: =COUNTIFS(IM!H5:H199,"x",IM!B5:B199,"Instruções Manutenção Mecânica") -> 8 | L8: =COUNTIFS(IM!H5:H199,"x",IM!B5:B199,"Instruções Manutenção Normativas e Gerenciais") -> 20 | U8: =SUM(C8:P8) -> 40
C10: Instrução de operaçaõ/Operating instruction
C11: Instruções de operação local | J11: Instruções de operação sistêmica | U11: TOTAL
B12: Total Instruções CTGBr "Por" | C12: =COUNTIFS(IO!F5:F276,"X",IO!B5:B276,"Instruções de operação local") -> 8 | J12: =COUNTIFS(IO!F5:F276,"X",IO!B5:B276,"Instruções de operação sistêmica") -> 76 | U12: =SUM(C12:P12) -> 84 | V12: =U12-U13 -> 15
B13: Total Instructions CTGBr "Eng" | C13: =COUNTIFS(IO!G5:G276,"X",IO!B5:B276,"Instruções de operação local") -> 6 | J13: =COUNTIFS(IO!G5:G276,"X",IO!B5:B276,"Instruções de operação sistêmica") -> 63 | U13: =SUM(C13:P13) -> 69
C15: Guia de manutenção/Maintenance guide
C16: JUR | D16: CHV | E16: SAG | F16: CN1 | G16: CN2 | H16: CPV | I16: TAQ | J16: ROS | K16: PLM | L16: RET | M16: ILS | N16: JUP | O16: STO | P16: GAR | Q16: ARN | R16: SDP | S16: COG | T16: UHE | U16: TOTAL
B17: Total Guias CTGBr "Por" | C17: =COUNTIFS(GM!$H$5:$H$1014,"X",GM!$C$5:$C$1014,"JUR") -> 50 | D17: =COUNTIFS(GM!$H$5:$H$1014,"X",GM!$C$5:$C$1014,"chv") -> 49 | E17: =COUNTIFS(GM!$H$5:$H$1014,"X",GM!$C$5:$C$1014,"SAG") -> 45 | F17: =COUNTIFS(GM!$H$5:$H$1014,"X",GM!$C$5:$C$1014,"CN1") -> 49 | G17: =COUNTIFS(GM!$H$5:$H$1014,"X",GM!$C$5:$C$1014,"CN2") -> 49 | H17: =COUNTIFS(GM!$H$5:$H$1014,"X",GM!$C$5:$C$1014,"CPV") -> 48 | I17: =COUNTIFS(GM!$H$5:$H$1014,"X",GM!$C$5:$C$1014,"TAQ") -> 48 | J17: =COUNTIFS(GM!$H$5:$H$1014,"X",GM!$C$5:$C$1014,"ROS") -> 49 | K17: =COUNTIFS(GM!$H$5:$H$1014,"X",GM!$C$5:$C$1014,"PLM") -> 41 | L17: =COUNTIFS(GM!$H$5:$H$1014,"X",GM!$C$5:$C$1014,"RET") -> 41 | M17: =COUNTIFS(GM!$H$5:$H$1014,"X",GM!$C$5:$C$1014,"ILS") -> 62 | N17: =COUNTIFS(GM!$H$5:$H$1014,"X",GM!$C$5:$C$1014,"JUP") -> 64 | O17: =COUNTIFS(GM!$H$5:$H$1014,"X",GM!$C$5:$C$1014,"STO") -> 48 | P17: =COUNTIFS(GM!$H$5:$H$1014,"X",GM!$C$5:$C$1014,"GAR") -> 58 | Q17: =COUNTIFS(GM!$H$5:$H$1014,"X",GM!$C$5:$C$1014,"ARN") -> 21 | R17: =COUNTIFS(GM!$H$5:$H$1014,"X",GM!$C$5:$C$1014,"SDP") -> 28 | S17: =COUNTIFS(GM!$H$5:$H$1014,"X",GM!$C$5:$C$1014,"COG") -> 1 | T17: =COUNTIFS(GM!$H$5:$H$1014,"X",GM!$C$5:$C$1014,"UHE") -> 0 | U17: =SUM(C17:T17) -> 751 | V17: =U17-U18 -> 53
B18: Total Guides CTGBr "Eng" | C18: =COUNTIFS(GM!$I$5:$I$1014,"X",GM!$C$5:$C$1014,"JUR") -> 47 | D18: =COUNTIFS(GM!$I$5:$I$1014,"X",GM!$C$5:$C$1014,"CHV") -> 46 | E18: =COUNTIFS(GM!$I$5:$I$1014,"X",GM!$C$5:$C$1014,"SAG") -> 42 | F18: =COUNTIFS(GM!$I$5:$I$1014,"X",GM!$C$5:$C$1014,"CN1") -> 45 | G18: =COUNTIFS(GM!$I$5:$I$1014,"X",GM!$C$5:$C$1014,"CN2") -> 45 | H18: =COUNTIFS(GM!$I$5:$I$1014,"X",GM!$C$5:$C$1014,"CPV") -> 44 | I18: =COUNTIFS(GM!$I$5:$I$1014,"X",GM!$C$5:$C$1014,"TAQ") -> 44 | J18: =COUNTIFS(GM!$I$5:$I$1014,"X",GM!$C$5:$C$1014,"ROS") -> 45 | K18: =COUNTIFS(GM!$I$5:$I$1014,"X",GM!$C$5:$C$1014,"PLM") -> 38 | L18: =COUNTIFS(GM!$I$5:$I$1014,"X",GM!$C$5:$C$1014,"RET") -> 38 | M18: =COUNTIFS(GM!$I$5:$I$1014,"X",GM!$C$5:$C$1014,"ILS") -> 58 | N18: =COUNTIFS(GM!$I$5:$I$1014,"X",GM!$C$5:$C$1014,"JUP") -> 60 | O18: =COUNTIFS(GM!$I$5:$I$1014,"X",GM!$C$5:$C$1014,"STO") -> 44 | P18: =COUNTIFS(GM!$I$5:$I$1014,"X",GM!$C$5:$C$1014,"GAR") -> 52 | Q18: =COUNTIFS(GM!$I$5:$I$1014,"X",GM!$C$5:$C$1014,"ARN") -> 21 | R18: =COUNTIFS(GM!$I$5:$I$1014,"X",GM!$C$5:$C$1014,"SDP") -> 28 | S18: =COUNTIFS(GM!$I$5:$I$1014,"X",GM!$C$5:$C$1014,"COG") -> 1 | T18: =COUNTIFS(GM!$I$5:$I$1014,"X",GM!$C$5:$C$1014,"UHE") -> 0 | U18: =SUM(C18:T18) -> 698
C20: Guia de operação/Operation guide
C21: JUR | D21: CHV | E21: SAG | F21: CN1 | G21: CN2 | H21: CPV | I21: TAQ | J21: ROS | K21: PLM | L21: RET | M21: ILS | N21: JUP | O21: STO | P21: GAR | Q21: ARN | R21: SDP | S21: COG | T21: UHE | U21: TOTAL
B22: Total Guias CTGBr "Por" | C22: =COUNTIFS(GO!G5:G457,"X",GO!C5:C457,"JUR") -> 8 | D22: =COUNTIFS(GO!G5:G457,"X",GO!C5:C457,"CHV") -> 8 | E22: =COUNTIFS(GO!G5:G457,"X",GO!C5:C457,"SAG") -> 8 | F22: =COUNTIFS(GO!G5:G457,"X",GO!C5:C457,"CN1") -> 7 | G22: =COUNTIFS(GO!G5:G457,"X",GO!C5:C457,"CN2") -> 7 | H22: =COUNTIFS(GO!G5:G457,"X",GO!C5:C457,"CPV") -> 8 | I22: =COUNTIFS(GO!G5:G457,"X",GO!C5:C457,"TAQ") -> 8 | J22: =COUNTIFS(GO!G5:G457,"X",GO!C5:C457,"ROS") -> 9 | K22: =COUNTIFS(GO!G5:G457,"X",GO!C5:C457,"PLM") -> 8 | L22: =COUNTIFS(GO!G5:G457,"X",GO!C5:C457,"RET") -> 8 | M22: =COUNTIFS(GO!G5:G457,"X",GO!C5:C457,"ILS") -> 73 | N22: =COUNTIFS(GO!G5:G457,"X",GO!C5:C457,"JUP") -> 41 | O22: =COUNTIFS(GO!G5:G457,"X",GO!C5:C457,"STO") -> 9 | P22: =COUNTIFS(GO!G5:G457,"X",GO!C5:C457,"GAR") -> 4 | Q22: =COUNTIFS(GO!G5:G457,"X",GO!C5:C457,"ARN") -> 3 | R22: =COUNTIFS(GO!G5:G457,"X",GO!C5:C457,"SDP") -> 0 | S22: =COUNTIFS(GO!G5:G457,"X",GO!C5:C457,"COG") -> 3 | T22: =COUNTIFS(GO!G5:G457,"X",GO!C5:C457,"UHE") -> 0 | U22: =SUM(C22:T22) -> 212 | V22: =U22-U23 -> 129
B23: Total Guides CTGBr "Eng" | C23: =COUNTIFS(GO!H5:H457,"X",GO!C5:C457,"JUR") -> 4 | D23: =COUNTIFS(GO!H5:H457,"X",GO!C5:C457,"CHV") -> 5 | E23: =COUNTIFS(GO!H5:H457,"X",GO!C5:C457,"SAG") -> 4 | F23: =COUNTIFS(GO!H5:H457,"X",GO!C5:C457,"CN1") -> 4 | G23: =COUNTIFS(GO!H5:H457,"X",GO!C5:C457,"CN2") -> 4 | H23: =COUNTIFS(GO!H5:H457,"X",GO!C5:C457,"CPV") -> 3 | I23: =COUNTIFS(GO!H5:H457,"X",GO!C5:C457,"TAQ") -> 3 | J23: =COUNTIFS(GO!H5:H457,"X",GO!C5:C457,"ROS") -> 4 | K23: =COUNTIFS(GO!H5:H457,"X",GO!C5:C457,"PLM") -> 4 | L23: =COUNTIFS(GO!H5:H457,"X",GO!C5:C457,"RET") -> 4 | M23: =COUNTIFS(GO!H5:H457,"X",GO!C5:C457,"ILS") -> 22 | N23: =COUNTIFS(GO!H5:H457,"X",GO!C5:C457,"JUP") -> 3 | O23: =COUNTIFS(GO!H5:H457,"X",GO!C5:C457,"STO") -> 9 | P23: =COUNTIFS(GO!H5:H457,"X",GO!C5:C457,"GAR") -> 4 | Q23: =COUNTIFS(GO!H5:H457,"X",GO!C5:C457,"ARN") -> 3 | R23: =COUNTIFS(GO!H5:H457,"X",GO!C5:C457,"SDP") -> 0 | S23: =COUNTIFS(GO!H5:H457,"X",GO!C5:C457,"COG") -> 3 | T23: =COUNTIFS(GO!H5:H457,"X",GO!C5:C457,"UHE") -> 0 | U23: =SUM(C23:T23) -> 83
C25: Protocolo/Protocol
C26: JUR | D26: CHV | E26: SAG | F26: CN1 | G26: CN2 | H26: CPV | I26: TAQ | J26: ROS | K26: PLM | L26: RET | M26: ILS | N26: JUP | O26: STO | P26: GAR | Q26: ARN | R26: SDP | S26: COG | T26: UHE | U26: TOTAL
B27: Total Protocolos CTGBr | C27: =COUNTIFS(PR!F5:F4771,"x",PR!A5:A4771,"JUR") -> 298 | D27: =COUNTIFS(PR!F5:F4771,"x",PR!A5:A4771,"CHV") -> 290 | E27: =COUNTIFS(PR!F5:F4771,"x",PR!A5:A4771,"SAG") -> 281 | F27: =COUNTIFS(PR!F5:F4771,"x",PR!A5:A4771,"CN1") -> 296 | G27: =COUNTIFS(PR!F5:F4771,"x",PR!A5:A4771,"CN2") -> 293 | H27: =COUNTIFS(PR!F5:F4771,"x",PR!A5:A4771,"CPV") -> 286 | I27: =COUNTIFS(PR!F5:F4771,"x",PR!A5:A4771,"TAQ") -> 311 | J27: =COUNTIFS(PR!F5:F4771,"x",PR!A5:A4771,"ROS") -> 308 | K27: =COUNTIFS(PR!F5:F4771,"x",PR!A5:A4771,"PLM") -> 252 | L27: =COUNTIFS(PR!F5:F4771,"x",PR!A5:A4771,"RET") -> 252 | M27: =COUNTIFS(PR!F5:F4771,"x",PR!A5:A4771,"ILS") -> 315 | N27: =COUNTIFS(PR!F5:F4771,"x",PR!A5:A4771,"JUP") -> 324 | O27: =COUNTIFS(PR!F5:F4771,"x",PR!A5:A4771,"STO") -> 273 | P27: =COUNTIFS(PR!F5:F4771,"x",PR!A5:A4771,"GAR") -> 306 | Q27: =COUNTIFS(PR!F5:F4771,"x",PR!A5:A4771,"ARN") -> 70 | R27: =COUNTIFS(PR!F5:F4771,"x",PR!A5:A4771,"SDP") -> 14 | S27: =COUNTIFS(PR!F5:F4771,"x",PR!A5:A4771,"COG") -> 0 | T27: =COUNTIFS(PR!F5:F4771,"x",PR!A5:A4771,"UHE") -> 0 | U27: =SUM(C27:T27) -> 4169 | V27: =U27-U28 -> 4054
B28: Total Protocols CTGBr "Eng" | C28: =COUNTIFS(PR!G5:G4771,"x",PR!A5:A4771,"JUR") -> 8 | D28: =COUNTIFS(PR!G5:G4771,"x",PR!A5:A4771,"CHV") -> 8 | E28: =COUNTIFS(PR!G5:G4771,"x",PR!A5:A4771,"SAG") -> 7 | F28: =COUNTIFS(PR!G5:G4771,"x",PR!A5:A4771,"CN1") -> 8 | G28: =COUNTIFS(PR!G5:G4771,"x",PR!A5:A4771,"CN2") -> 8 | H28: =COUNTIFS(PR!G5:G4771,"x",PR!A5:A4771,"CPV") -> 8 | I28: =COUNTIFS(PR!G5:G4771,"x",PR!A5:A4771,"TAQ") -> 8 | J28: =COUNTIFS(PR!G5:G4771,"x",PR!A5:A4771,"ROS") -> 8 | K28: =COUNTIFS(PR!G5:G4771,"x",PR!A5:A4771,"PLM") -> 8 | L28: =COUNTIFS(PR!G5:G4771,"x",PR!A5:A4771,"RET") -> 8 | M28: =COUNTIFS(PR!G5:G4771,"x",PR!A5:A4771,"ILS") -> 10 | N28: =COUNTIFS(PR!G5:G4771,"x",PR!A5:A4771,"JUP") -> 8 | O28: =COUNTIFS(PR!G5:G4771,"x",PR!A5:A4771,"STO") -> 8 | P28: =COUNTIFS(PR!G5:G4771,"x",PR!A5:A4771,"GAR") -> 8 | Q28: =COUNTIFS(PR!G5:G4771,"x",PR!A5:A4771,"ARN") -> 1 | R28: =COUNTIFS(PR!G5:G4771,"x",PR!A5:A4771,"SDP") -> 1 | S28: =COUNTIFS(PR!G5:G4771,"x",PR!A5:A4771,"COG") -> 0 | T28: =COUNTIFS(PR!G5:G4771,"x",PR!A5:A4771,"UHE") -> 0 | U28: =SUM(C28:T28) -> 115
C30: Manual de manutenção/Maintenance manual
C31: JUR | D31: CHV | E31: SAG | F31: CN1 | G31: CN2 | H31: CPV | I31: TAQ | J31: ROS | K31: PLM | L31: RET | M31: ILS | N31: JUP | O31: STO | P31: GAR | Q31: ARN | R31: SDP | S31: COG | T31: UHE | U31: TOTAL
B32: Total Manuals CTGBr | C32: =COUNTIFS(MM!M6:M798,"Publicado",MM!C6:C798,"JUR") -> 21 | D32: =COUNTIFS(MM!M6:M798,"Publicado",MM!C6:C798,"CHV") -> 19 | E32: =COUNTIFS(MM!M6:M798,"Publicado",MM!C6:C798,"SAG") -> 25 | F32: =COUNTIFS(MM!M6:M798,"Publicado",MM!C6:C798,"CN1") -> 32 | G32: =COUNTIFS(MM!M6:M798,"Publicado",MM!C6:C798,"CN2") -> 33 | H32: =COUNTIFS(MM!M6:M798,"Publicado",MM!C6:C798,"CPV") -> 41 | I32: =COUNTIFS(MM!M6:M798,"Publicado",MM!C6:C798,"TAQ") -> 24 | J32: =COUNTIFS(MM!M6:M798,"Publicado",MM!C6:C798,"ROS") -> 40 | K32: =COUNTIFS(MM!M6:M798,"Publicado",MM!C6:C798,"PLM") -> 16 | L32: =COUNTIFS(MM!M6:M798,"Publicado",MM!C6:C798,"RET") -> 15 | M32: =COUNTIFS(MM!M6:M798,"Publicado",MM!C6:C798,"ILS") -> 120 | N32: =COUNTIFS(MM!M6:M798,"Publicado",MM!C6:C798,"JUP") -> 47 | O32: =COUNTIFS(MM!M6:M798,"Publicado",MM!C6:C798,"STO") -> 4 | P32: =COUNTIFS(MM!M6:M798,"Publicado",MM!C6:C798,"GAR") -> 38 | Q32: =COUNTIFS(MM!M6:M798,"Publicado",MM!C6:C798,"ARN") -> 0 | R32: =COUNTIFS(MM!M6:M798,"Publicado",MM!C6:C798,"SDP") -> 0 | S32: =COUNTIFS(MM!M6:M798,"Publicado",MM!C6:C798,"COG") -> 2 | T32: =COUNTIFS(MM!M6:M798,"Publicado",MM!C6:C798,"UHE") -> 3 | U32: =SUM(C32:T32) -> 480
C34: Manual de operação/Operation Manual
C35: JUR | D35: CHV | E35: SAG | F35: CN1 | G35: CN2 | H35: CPV | I35: TAQ | J35: ROS | K35: PLM | L35: RET | M35: ILS | N35: JUP | O35: STO | P35: GAR | Q35: ARN | R35: SDP | S35: COG | T35: UHE | U35: TOTAL
B36: Total Manuais CTGBr "Por" | C36: =COUNTIFS(MO!K6:K600,"Publicado",MO!C6:C600,"JUR") -> 20 | D36: =COUNTIFS(MO!K6:K600,"Publicado",MO!C6:C600,"CHV") -> 28 | E36: =COUNTIFS(MO!K6:K600,"Publicado",MO!C6:C600,"SAG") -> 21 | F36: =COUNTIFS(MO!K6:K600,"Publicado",MO!C6:C600,"CN1") -> 19 | G36: =COUNTIFS(MO!K6:K600,"Publicado",MO!C6:C600,"CN2") -> 16 | H36: =COUNTIFS(MO!K6:K600,"Publicado",MO!C6:C600,"CPV") -> 16 | I36: =COUNTIFS(MO!K6:K600,"Publicado",MO!C6:C600,"TAQ") -> 21 | J36: =COUNTIFS(MO!K6:K600,"Publicado",MO!C6:C600,"ROS") -> 19 | K36: =COUNTIFS(MO!K6:K600,"Publicado",MO!C6:C600,"PLM") -> 25 | L36: =COUNTIFS(MO!K6:K600,"Publicado",MO!C6:C600,"RET") -> 25 | M36: =COUNTIFS(MO!K6:K600,"Publicado",MO!C6:C600,"ILS") -> 11 | N36: =COUNTIFS(MO!K6:K600,"Publicado",MO!C6:C600,"JUP") -> 27 | O36: =COUNTIFS(MO!K6:K600,"Publicado",MO!C6:C600,"STO") -> 10 | P36: =COUNTIFS(MO!K6:K600,"Publicado",MO!C6:C600,"GAR") -> 0 | Q36: =COUNTIFS(MO!K6:K600,"Publicado",MO!C6:C600,"ARN") -> 0 | R36: =COUNTIFS(MO!K6:K600,"Publicado",MO!C6:C600,"SDP") -> 0 | S36: =COUNTIFS(MO!K6:K600,"Publicado",MO!C6:C600,"COG") -> 0 | T36: =COUNTIFS(MO!K6:K600,"Publicado",MO!C6:C600,"UHE") -> 0 | U36: =SUM(C36:T36) -> 258
B37: Total Manuals CTGBr "Eng" | C37: =COUNTIFS(MO!M6:M600,"X",MO!C6:C600,"JUR") -> 20 | D37: =COUNTIFS(MO!M6:M600,"X",MO!C6:C600,"CHV") -> 28 | E37: =COUNTIFS(MO!M6:M600,"X",MO!C6:C600,"SAG") -> 21 | F37: =COUNTIFS(MO!M6:M600,"X",MO!C6:C600,"CN1") -> 19 | G37: =COUNTIFS(MO!M6:M600,"X",MO!C6:C600,"CN2") -> 16 | H37: =COUNTIFS(MO!M6:M600,"X",MO!C6:C600,"CPV") -> 0 | I37: =COUNTIFS(MO!M6:M600,"X",MO!C6:C600,"TAQ") -> 0 | J37: =COUNTIFS(MO!M6:M600,"X",MO!C6:C600,"ROS") -> 0 | K37: =COUNTIFS(MO!M6:M600,"X",MO!C6:C600,"PLM") -> 25 | L37: =COUNTIFS(MO!M6:M600,"X",MO!C6:C600,"RET") -> 25 | M37: =COUNTIFS(MO!M6:M600,"X",MO!C6:C600,"ILS") -> 0 | N37: =COUNTIFS(MO!M6:M600,"X",MO!C6:C600,"JUP") -> 0 | O37: =COUNTIFS(MO!M6:M600,"X",MO!C6:C600,"STO") -> 10 | P37: =COUNTIFS(MO!M6:M600,"X",MO!C6:C600,"GAR") -> 0 | Q37: =COUNTIFS(MO!M6:M600,"X",MO!C6:C600,"ARN") -> 0 | R37: =COUNTIFS(MO!M6:M600,"X",MO!C6:C600,"SDP") -> 0 | S37: =COUNTIFS(MO!M6:M600,"X",MO!C6:C600,"COG") -> 0 | T37: =COUNTIFS(MO!M6:M600,"X",MO!C6:C600,"UHE") -> 0 | U37: =SUM(C37:T37) -> 164
C39: Política/Politic
C40: Políticas "Por" | J40: Politics "Eng" | U40: TOTAL
B41: Total Politics CTGBr | C41: =COUNTIFS(POL!E5:E83,"X") -> 19 | J41: =COUNTIFS(POL!F5:F83,"X") -> 19 | U41: =SUM(C41:T41) -> 38

Sheet POL
A1: POL - POLÍTICAS PMS (PMS POLICIES)
I2: TOTAL
D3: Area | E3: =COUNTIF(E4:E80,"X") -> 19 | F3: =COUNTIF(F4:F80,"X") -> 19 | I3: =COUNTIF(I4:I4983,"Publicado") -> 18 | L3: Em dia | M3: Alerta | N3: Vencido | Q3: =TODAY() -> 46198
A4: NÚMERO | B4: DESCRIÇÃO | E4: Por. | F4: Ing. | G4: Data aprovação | H4: Data Vencimento | I4: Status | J4: Status validade | K4: =TODAY() -> 46198 | Q4: Dias que falta para vencer
A5: POL-PMS-001 | B5: Política de Gestão da Produção e Inovação | C5: Production and Technology Management Policy | D5: Engenharia Eletromecânica | E5: X | F5: X | G5: 45895 | H5: =G5+1096 -> 46991 | I5: Publicado | J5: =IF(K5="","",IF(K5>1095,"Vencido",IF(K5>910,"Alerta",IF(K5>820,"Alerta",IF(K5>730,"Alerta",IF(K5>=0,"Em dia","Vencido")))))) -> Em dia | K5: =$K$4-G5 -> 303 | Q5: =H5-$Q$3 -> 793
A6: POL-PMS-002 | B6: Política de Gestão dos Padrões Técnicos | C6: Technical Standards Management Policy | D6: Engenharia Eletromecânica | E6: X | F6: X | G6: 45895 | H6: =G6+1096 -> 46991 | I6: Publicado | J6: =IF(K6="","",IF(K6>1095,"Vencido",IF(K6>910,"Alerta",IF(K6>820,"Alerta",IF(K6>730,"Alerta",IF(K6>=0,"Em dia","Vencido")))))) -> Em dia | K6: =$K$4-G6 -> 303 | Q6: =H6-$Q$3 -> 793
A7: POL-PMS-003 | B7: Procedimento de gestão operacional das UHEs | C7: Operation Management Procedure | D7: Engenharia Eletromecânica | E7: X | F7: X | G7: 43952 | H7: =G7+1096 -> 45048 | I7: Publicado | J7: =IF(K7="","",IF(K7>1095,"Vencido",IF(K7>910,"Alerta",IF(K7>820,"Alerta",IF(K7>730,"Alerta",IF(K7>=0,"Em dia","Vencido")))))) -> Vencido | K7: =$K$4-G7 -> 2246 | Q7: =H7-$Q$3 -> -1150
A8: POL-PMS-004 | B8: Gestão da manutenção e modernização das UHEs | C8: Maintenance and Modernization Management | D8: Engenharia Eletromecânica | E8: X | F8: X | G8: 45202 | H8: =G8+1096 -> 46298 | I8: Publicado | J8: =IF(K8="","",IF(K8>1095,"Vencido",IF(K8>910,"Alerta",IF(K8>820,"Alerta",IF(K8>730,"Alerta",IF(K8>=0,"Em dia","Vencido")))))) -> Alerta | K8: =$K$4-G8 -> 996 | Q8: =H8-$Q$3 -> 100
A9: POL-PMS-005 | B9: Gerenciamento de Saúde e Segurança na Operação e Manutenção | C9: Safe Operation Maintenance Management | D9: Segurança | E9: X | F9: X | G9: 45202 | H9: =G9+1096 -> 46298 | I9: Publicado | J9: =IF(K9="","",IF(K9>1095,"Vencido",IF(K9>910,"Alerta",IF(K9>820,"Alerta",IF(K9>730,"Alerta",IF(K9>=0,"Em dia","Vencido")))))) -> Alerta | K9: =$K$4-G9 -> 996 | Q9: =H9-$Q$3 -> 100
A10: POL-PMS-006 | B10: Investigação de Acidentes e Incidentes | C10: Accidents and Incident Investigation | D10: Engenharia Eletromecânica | I10: Cancelada | J10: =IF(K10="","",IF(K10>1095,"Vencido",IF(K10>910,"Alerta",IF(K10>820,"Alerta",IF(K10>730,"Alerta",IF(K10>=0,"Em dia","Vencido")))))) -> Vencido | K10: =$K$4-G10 -> 46198
A11: POL-PMS-007 | B11: Identificação e Controle de Riscos Ocultos | C11: Hidden Risk Identification Control | D11: Engenharia Eletromecânica | E11: X | F11: X | G11: 45202 | H11: =G11+1096 -> 46298 | I11: Publicado | J11: =IF(K11="","",IF(K11>1095,"Vencido",IF(K11>910,"Alerta",IF(K11>820,"Alerta",IF(K11>730,"Alerta",IF(K11>=0,"Em dia","Vencido")))))) -> Alerta | K11: =$K$4-G11 -> 996 | Q11: =H11-$Q$3 -> 100
A12: POL-PMS-010 | B12: Gestão das alterações de projeto | C12: Management of Design changes | D12: Engenharia Eletromecânica | E12: X | F12: X | G12: 45202 | H12: =G12+1096 -> 46298 | I12: Publicado | J12: =IF(K12="","",IF(K12>1095,"Vencido",IF(K12>910,"Alerta",IF(K12>820,"Alerta",IF(K12>730,"Alerta",IF(K12>=0,"Em dia","Vencido")))))) -> Alerta | K12: =$K$4-G12 -> 996 | Q12: =H12-$Q$3 -> 100
A13: POL-PMS-011 | B13: Política de Gestão da Calibração dos instrumentos | C13: Instruments Calibration Management Policy | D13: Engenharia Eletromecânica | E13: X | F13: X | G13: 43983 | H13: =G13+1096 -> 45079 | I13: Publicado | J13: =IF(K13="","",IF(K13>1095,"Vencido",IF(K13>910,"Alerta",IF(K13>820,"Alerta",IF(K13>730,"Alerta",IF(K13>=0,"Em dia","Vencido")))))) -> Vencido | K13: =$K$4-G13 -> 2215 | Q13: =H13-$Q$3 -> -1119
A14: POL-PMS-012 | B14: Política de Segurança Cibernética para o Ambiente SCADA | C14: Cybersecurity Policy for the Scada Environment | D14: Engenharia Eletromecânica | E14: X | F14: X | G14: 44187 | H14: =G14+1096 -> 45283 | I14: Publicado | J14: =IF(K14="","",IF(K14>1095,"Vencido",IF(K14>910,"Alerta",IF(K14>820,"Alerta",IF(K14>730,"Alerta",IF(K14>=0,"Em dia","Vencido")))))) -> Vencido | K14: =$K$4-G14 -> 2011 | Q14: =H14-$Q$3 -> -915
A15: POL-PMS-014 | B15: Gerenciamento de Projetos da Engenharia | C15: Engineering Projects Management | D15: Engenharia CAPEX | E15: X | F15: X | G15: 45686 | H15: =G15+1096 -> 46782 | I15: Publicado | J15: =IF(K15="","",IF(K15>1095,"Vencido",IF(K15>910,"Alerta",IF(K15>820,"Alerta",IF(K15>730,"Alerta",IF(K15>=0,"Em dia","Vencido")))))) -> Em dia | K15: =$K$4-G15 -> 512 | P15: =G15+1080 -> 46766 | Q15: =H15-$Q$3 -> 584
A16: POL-PMS-015 | B16: Gestão de Mudanças de Escopo em Projetos de Engenharia | C16: Scope Changes Management for Engineering Projects | D16: Engenharia CAPEX | E16: X | F16: X | G16: 45686 | H16: =G16+1096 -> 46782 | I16: Publicado | J16: =IF(K16="","",IF(K16>1095,"Vencido",IF(K16>910,"Alerta",IF(K16>820,"Alerta",IF(K16>730,"Alerta",IF(K16>=0,"Em dia","Vencido")))))) -> Em dia | K16: =$K$4-G16 -> 512 | P16: =G16+1080 -> 46766 | Q16: =H16-$Q$3 -> 584
A17: POL-PMS-016 | B17: Comissionamento e Entrega de Ativos | C17: Commissioning and Assets Handover | D17: Engenharia CAPEX | E17: X | F17: X | G17: 45686 | H17: =G17+1096 -> 46782 | I17: Publicado | J17: =IF(K17="","",IF(K17>1095,"Vencido",IF(K17>910,"Alerta",IF(K17>820,"Alerta",IF(K17>730,"Alerta",IF(K17>=0,"Em dia","Vencido")))))) -> Em dia | K17: =$K$4-G17 -> 512 | Q17: =H17-$Q$3 -> 584
A18: POL-PMS-017 | B18: Abertura e Encerramento de Projetos | C18: Opening and Closure of Engineering Projects | D18: Engenharia CAPEX | E18: X | F18: X | G18: 45686 | H18: =G18+1096 -> 46782 | I18: Publicado | J18: =IF(K18="","",IF(K18>1095,"Vencido",IF(K18>910,"Alerta",IF(K18>820,"Alerta",IF(K18>730,"Alerta",IF(K18>=0,"Em dia","Vencido")))))) -> Em dia | K18: =$K$4-G18 -> 512 | P18: =G18+1080 -> 46766 | Q18: =H18-$Q$3 -> 584
A19: POL-PMS-018 | B19: Gestão de Riscos dos Projetos da Engenharia | C19: Engineering Project Risk Management – | D19: Engenharia CAPEX | E19: X | F19: X | G19: 45686 | H19: =G19+1096 -> 46782 | I19: Publicado | J19: =IF(K19="","",IF(K19>1095,"Vencido",IF(K19>910,"Alerta",IF(K19>820,"Alerta",IF(K19>730,"Alerta",IF(K19>=0,"Em dia","Vencido")))))) -> Em dia | K19: =$K$4-G19 -> 512 | P19: =G19+1080 -> 46766 | Q19: =H19-$Q$3 -> 584
A20: POL-PMS-019 | B20: Lições Aprendidas – Projetos da Engenharia | C20: Lessons Learned – Engineering projects | D20: Engenharia CAPEX | E20: X | F20: X | G20: 45686 | H20: =G20+1096 -> 46782 | I20: Publicado | J20: =IF(K20="","",IF(K20>1095,"Vencido",IF(K20>910,"Alerta",IF(K20>820,"Alerta",IF(K20>730,"Alerta",IF(K20>=0,"Em dia","Vencido")))))) -> Em dia | K20: =$K$4-G20 -> 512 | P20: =G20+1080 -> 46766 | Q20: =H20-$Q$3 -> 584
A21: POL-PMS-020 | B21: Monitoramento e Controle de Cronogramas de Projetos de Engenharia | C21: Monitoring and Control of Project Schedules | D21: Engenharia CAPEX | E21: X | F21: X | I21: Cancelada | J21: =IF(K21="","",IF(K21>1095,"Vencido",IF(K21>910,"Alerta",IF(K21>820,"Alerta",IF(K21>730,"Alerta",IF(K21>=0,"Em dia","Vencido")))))) -> Vencido | K21: =$K$4-G21 -> 46198 | P21: =G21+1080 -> 1080
A22: POL-PMS-021 | B22: Politica de Gestão Orçamentária de Projetos CAPEX da Engenharia | C22: Engineering Capex Project Budget Management Policy | D22: Engenharia CAPEX | E22: X | F22: X | G22: 45769 | H22: =G22+1096 -> 46865 | I22: Publicado | J22: =IF(K22="","",IF(K22>1095,"Vencido",IF(K22>910,"Alerta",IF(K22>820,"Alerta",IF(K22>730,"Alerta",IF(K22>=0,"Em dia","Vencido")))))) -> Em dia | K22: =$K$4-G22 -> 429 | P22: =G22+1080 -> 46849 | Q22: =H22-$Q$3 -> 667
A23: PRD-SST-004 | B23: Gestão Equipamento e Ferramentas de Segurança | C23: Equipment Safety and Safety Tools Management | D23: Segurança | E23: X | F23: X | G23: 45274 | H23: =G23+1096 -> 46370 | I23: Publicado | J23: =IF(K23="","",IF(K23>1095,"Vencido",IF(K23>910,"Alerta",IF(K23>820,"Alerta",IF(K23>730,"Alerta",IF(K23>=0,"Em dia","Vencido")))))) -> Alerta | K23: =$K$4-G23 -> 924 | P23: =G23+1080 -> 46354 | Q23: =H23-$Q$3 -> 172
A24: PRD-SST-005 | B24: Cód de Gerenciamento de Despesas de Saúde e Segurança | C24: Expenses Management Code HSE | D24: Segurança | E24: X | F24: X | G24: 45379 | H24: =G24+1096 -> 46475 | I24: Publicado | J24: =IF(K24="","",IF(K24>1095,"Vencido",IF(K24>910,"Alerta",IF(K24>820,"Alerta",IF(K24>730,"Alerta",IF(K24>=0,"Em dia","Vencido")))))) -> Alerta | K24: =$K$4-G24 -> 819 | P24: =G24+1080 -> 46459 | Q24: =H24-$Q$3 -> 277

Sheet IM
B2: IM - INSTRUÇÕES DE MANUTENÇÃO (MAINTENANCE INSTRUCTIONS)
G3: =COUNTIF(G4:G300,"X") -> 90 | H3: =COUNTIF(H4:H300,"X") -> 40 | S3: =TODAY() -> 46198
B4: TIPO/TYPE | C4: NUMERO / NUMBER | D4: DESCRIÇÃO | E4: DESCRIPTION | F4: ÁREA | G4: Por. | H4: Ing. | I4: Data aprovação | J4: Data Vencimento | K4: Status | L4: Status data | M4: Revisão/Novo | N4: =TODAY() -> 46198 | S4: Dias que falta para vencer
B5: Instruções Manutenção Normativas e Gerenciais | C5: IM-ENG-001 | D5: Diretrizes da Manutenção | E5: Maintenance Guidelines | F5: ENGENHARIA CONFIABILIDADE E PERFORMANCE | G5: X | H5: X | I5: 45595 | J5: =I5+1096 -> 46691 | K5: Publicado | L5: =IF(N5="","",IF(N5>1095,"Vencido",IF(N5>910,"Alerta",IF(N5>820,"Alerta",IF(N5>730,"Alerta",IF(N5>=0,"Em dia","Vencido")))))) -> Em dia | N5: =$N$4-I5 -> 603 | S5: =J5-$S$3 -> 493
B6: Instruções Manutenção Normativas e Gerenciais | C6: IM-ENG-002 | D6: Instrução Treinam Tec Prod Eletric e Mec | E6: Training policy for electrical and mechanical technicians | F6: ENGENHARIA CONFIABILIDADE E PERFORMANCE | G6: X | I6: 45202 | J6: =I6+1096 -> 46298 | K6: Publicado | L6: =IF(N6="","",IF(N6>1095,"Vencido",IF(N6>910,"Alerta",IF(N6>820,"Alerta",IF(N6>730,"Alerta",IF(N6>=0,"Em dia","Vencido")))))) -> Alerta | N6: =$N$4-I6 -> 996 | S6: =J6-$S$3 -> 100
B7: Instruções Manutenção Normativas e Gerenciais | C7: IM-ENG-003 | D7: Procedimento analise e comunic deslig. forçado UG | E7: Procedure for analyzing and reporting forced outages | F7: ENGENHARIA CONFIABILIDADE E PERFORMANCE | G7: X | H7: X | I7: 45895 | J7: =I7+1096 -> 46991 | K7: Publicado | L7: =IF(N7="","",IF(N7>1095,"Vencido",IF(N7>910,"Alerta",IF(N7>820,"Aviso",IF(N7>730,"Comunicado",IF(N7>=0,"Em dia","Vencido")))))) -> Em dia | N7: =$N$4-I7 -> 303 | S7: =J7-$S$3 -> 793
B8: Instruções Manutenção Elétrica | C8: IM-ENG-004 | D8: Medição de Aterramento | E8: Procedure for inspection of ligthning arrester and grounding systems | F8: ENGENHARIA ELÉTRICA | G8: X | I8: 45202 | J8: =I8+1096 -> 46298 | K8: Publicado | L8: =IF(N8="","",IF(N8>1095,"Vencido",IF(N8>910,"Alerta",IF(N8>820,"Alerta",IF(N8>730,"Alerta",IF(N8>=0,"Em dia","Vencido")))))) -> Alerta | N8: =$N$4-I8 -> 996 | S8: =J8-$S$3 -> 100
B9: Instruções Manutenção Mecânica | C9: IM-ENG-005 | D9: Vasos de Pressão | E9: Procedure for testing pressure vessels | F9: ENGENHARIA MECÂNICA | G9: X | H9: X | I9: 45895 | J9: =I9+1096 -> 46991 | K9: Publicado | L9: =IF(N9="","",IF(N9>1095,"Vencido",IF(N9>910,"Alerta",IF(N9>820,"Aviso",IF(N9>730,"Comunicado",IF(N9>=0,"Em dia","Vencido")))))) -> Em dia | N9: =$N$4-I9 -> 303 | S9: =J9-$S$3 -> 793
B10: Instruções Manutenção Normativas e Gerenciais | C10: IM-ENG-006 | D10: Utilização do Maximo 7.6 | E10: Work Order - Quick Reference Manual (MAXIMO®) | F10: ENGENHARIA CONFIABILIDADE E PERFORMANCE | G10: X | H10: X | I10: 45595 | J10: =I10+1096 -> 46691 | K10: Publicado | L10: =IF(N10="","",IF(N10>1095,"Vencido",IF(N10>910,"Alerta",IF(N10>820,"Aviso",IF(N10>730,"Comunicado",IF(N10>=0,"Em dia","Vencido")))))) -> Em dia | N10: =$N$4-I10 -> 603 | S10: =J10-$S$3 -> 493
B11: Instruções Manutenção Mecânica | C11: IM-ENG-007 | D11: Procedimento para recuperar Cavitação | E11: Procedures for recovering Cavitation | F11: ENGENHARIA MECÂNICA | G11: X | H11: X | I11: 44914 | J11: =I11+1096 -> 46010 | K11: Publicado | L11: =IF(N11="","",IF(N11>1095,"Vencido",IF(N11>910,"Alerta",IF(N11>820,"Alerta",IF(N11>730,"Alerta",IF(N11>=0,"Em dia","Vencido")))))) -> Vencido | N11: =$N$4-I11 -> 1284 | S11: =J11-$S$3 -> -188
B12: Instruções Manutenção Elétrica | C12: IM-ENG-008 | D12: Teste de Chama em Reles Buchholz | E12: Procedure to perform Flame Test (relay Buchhoz) | F12: ENGENHARIA ELÉTRICA | G12: X | I12: 45538 | J12: =I12+1096 -> 46634 | K12: Publicado | L12: =IF(N12="","",IF(N12>1095,"Vencido",IF(N12>910,"Alerta",IF(N12>820,"Aviso",IF(N12>730,"Comunicado",IF(N12>=0,"Em dia","Vencido")))))) -> Em dia | N12: =$N$4-I12 -> 660 | S12: =J12-$S$3 -> 436
B13: Instruções Manutenção Elétrica | C13: IM-ENG-009 | D13: Ensaio de Isolação em Geradores e Motores | E13: Insulation Testing in Generators and Engines | F13: ENGENHARIA ELÉTRICA | I13: - | K13: Cancelada | N13: =$N$4-I13 -> #VALUE!
B14: Instruções Manutenção Normativas e Gerenciais | C14: IM-ENG-010 | D14: Procedimento de Impedimento Para Intervenções no Gerador | E14: Procedure to isolate generator during maintenance | F14: ENGENHARIA CONFIABILIDADE E PERFORMANCE | I14: - | K14: Cancelada | N14: =$N$4-I14 -> #VALUE!
B15: Instruções Manutenção Elétrica | C15: IM-ENG-013 | D15: Ensaios de Termovisão | E15: Procedure for Thermovison testings | F15: ENGENHARIA ELÉTRICA | G15: X | H15: X | I15: 45595 | J15: =I15+1096 -> 46691 | K15: Publicado | L15: =IF(N15="","",IF(N15>1095,"Vencido",IF(N15>910,"Alerta",IF(N15>820,"Aviso",IF(N15>730,"Comunicado",IF(N15>=0,"Em dia","Vencido")))))) -> Em dia | N15: =$N$4-I15 -> 603 | S15: =J15-$S$3 -> 493
B16: Instruções Manutenção Normativas e Gerenciais | C16: IM-ENG-014 | D16: Gerenciamento Grandes Manutenções | E16: Procedure for manage major maintenances | F16: ENGENHARIA CONFIABILIDADE E PERFORMANCE | G16: X | I16: 44868 | J16: =I16+1096 -> 45964 | K16: Publicado | L16: =IF(N16="","",IF(N16>1095,"Vencido",IF(N16>910,"Alerta",IF(N16>820,"Alerta",IF(N16>730,"Alerta",IF(N16>=0,"Em dia","Vencido")))))) -> Vencido | N16: =$N$4-I16 -> 1330 | S16: =J16-$S$3 -> -234
B17: Instruções Manutenção Normativas e Gerenciais | C17: IM-ENG-015 | D17: Auditoria Processos OeM | E17: Audit Processes O&M | F17: ENGENHARIA CONFIABILIDADE E PERFORMANCE | G17: X | H17: X | I17: 44631 | J17: =I17+1096 -> 45727 | K17: Publicado | L17: =IF(N17="","",IF(N17>1095,"Vencido",IF(N17>910,"Alerta",IF(N17>820,"Alerta",IF(N17>730,"Alerta",IF(N17>=0,"Em dia","Vencido")))))) -> Vencido | N17: =$N$4-I17 -> 1567 | R17: =I17+1080 -> 45711 | S17: =J17-$S$3 -> -471
B18: Instruções Manutenção Mecânica | C18: IM-ENG-016 | D18: Utilização do Nível Ótico N3 | E18: Use of Optical Level N3 | F18: ENGENHARIA MECÂNICA | G18: X | I18: 45202 | J18: =I18+1096 -> 46298 | K18: Publicado | L18: =IF(N18="","",IF(N18>1095,"Vencido",IF(N18>910,"Alerta",IF(N18>820,"Alerta",IF(N18>730,"Alerta",IF(N18>=0,"Em dia","Vencido")))))) -> Alerta | N18: =$N$4-I18 -> 996 | S18: =J18-$S$3 -> 100
B19: Instruções Manutenção Elétrica | C19: IM-ENG-017 | D19: Coleta e Análise de Óleo Isolante | E19: Procedures to take sample of isolating oil | F19: ENGENHARIA ELÉTRICA | G19: X | H19: X | I19: 45743 | J19: =I19+1096 -> 46839 | K19: Publicado | L19: =IF(N19="","",IF(N19>1095,"Vencido",IF(N19>910,"Alerta",IF(N19>820,"Aviso",IF(N19>730,"Comunicado",IF(N19>=0,"Em dia","Vencido")))))) -> Em dia | N19: =$N$4-I19 -> 455 | S19: =J19-$S$3 -> 641
B20: Instruções Manutenção Mecânica | C20: IM-ENG-018 | D20: Monitoramento e tratam oleo lubrific | E20: Lubrication Oil Condition Monitoring | F20: ENGENHARIA MECÂNICA | G20: X | H20: x | I20: 45895 | J20: =I20+1096 -> 46991 | K20: Publicado | L20: =IF(N20="","",IF(N20>1095,"Vencido",IF(N20>910,"Alerta",IF(N20>820,"Aviso",IF(N20>730,"Comunicado",IF(N20>=0,"Em dia","Vencido")))))) -> Em dia | N20: =$N$4-I20 -> 303 | S20: =J20-$S$3 -> 793
B21: Instruções Manutenção Elétrica | C21: IM-ENG-019 | D21: Conjunto de Aterramento Temporário para Manutenção | E21: Temporary grounding set for maintenance | F21: ENGENHARIA ELÉTRICA | G21: X | H21: X | I21: 45462 | J21: =I21+1096 -> 46558 | K21: Publicado | L21: =IF(N21="","",IF(N21>1095,"Vencido",IF(N21>910,"Alerta",IF(N21>820,"Aviso",IF(N21>730,"Comunicado",IF(N21>=0,"Em dia","Vencido")))))) -> Comunicado | N21: =$N$4-I21 -> 736 | R21: =I21+1080 -> 46542 | S21: =J21-$S$3 -> 360
B22: Instruções Manutenção Normativas e Gerenciais | C22: IM-ENG-020 | D22: Manutenções Preventivas Periódicas 0 | E22: Periodic Preventive Maintenance type 0 | F22: ENGENHARIA CONFIABILIDADE E PERFORMANCE | G22: X | I22: 44868 | J22: =I22+1096 -> 45964 | K22: Publicado | L22: =IF(N22="","",IF(N22>1095,"Vencido",IF(N22>910,"Alerta",IF(N22>820,"Alerta",IF(N22>730,"Alerta",IF(N22>=0,"Em dia","Vencido")))))) -> Vencido | N22: =$N$4-I22 -> 1330 | S22: =J22-$S$3 -> -234
B23: Instruções Manutenção Normativas e Gerenciais | C23: IM-ENG-021 | D23: Manutenções Preventivas Periódicas 1 | E23: Periodic Preventive Maintenance type 1 | F23: ENGENHARIA CONFIABILIDADE E PERFORMANCE | G23: X | I23: 44868 | J23: =I23+1096 -> 45964 | K23: Publicado | L23: =IF(N23="","",IF(N23>1095,"Vencido",IF(N23>910,"Alerta",IF(N23>820,"Alerta",IF(N23>730,"Alerta",IF(N23>=0,"Em dia","Vencido")))))) -> Vencido | N23: =$N$4-I23 -> 1330 | S23: =J23-$S$3 -> -234
B24: Instruções Manutenção Normativas e Gerenciais | C24: IM-ENG-022 | D24: Manutenções Preventivas Periódicas 2 | E24: Periodic Preventive Maintenance type 2 | F24: ENGENHARIA CONFIABILIDADE E PERFORMANCE | G24: X | I24: 44868 | J24: =I24+1096 -> 45964 | K24: Publicado | L24: =IF(N24="","",IF(N24>1095,"Vencido",IF(N24>910,"Alerta",IF(N24>820,"Alerta",IF(N24>730,"Alerta",IF(N24>=0,"Em dia","Vencido")))))) -> Vencido | N24: =$N$4-I24 -> 1330 | S24: =J24-$S$3 -> -234
B25: Instruções Manutenção Mecânica | C25: IM-ENG-023 | D25: Sistema de Ar Comprimido | E25: Procedures for maintenance air compressed equipments | F25: ENGENHARIA MECÂNICA | G25: X | I25: 45202 | J25: =I25+1096 -> 46298 | K25: Publicado | L25: =IF(N25="","",IF(N25>1095,"Vencido",IF(N25>910,"Alerta",IF(N25>820,"Alerta",IF(N25>730,"Alerta",IF(N25>=0,"Em dia","Vencido")))))) -> Alerta | N25: =$N$4-I25 -> 996 | S25: =J25-$S$3 -> 100
B26: Instruções Manutenção Elétrica | C26: IM-ENG-026 | D26: Formulário com Medidas de Segurança | E26: Safety risk control measures | F26: ENGENHARIA ELÉTRICA | G26: X | H26: X | I26: 45462 | J26: =I26+1096 -> 46558 | K26: Publicado | L26: =IF(N26="","",IF(N26>1095,"Vencido",IF(N26>910,"Alerta",IF(N26>820,"Aviso",IF(N26>730,"Comunicado",IF(N26>=0,"Em dia","Vencido")))))) -> Comunicado | N26: =$N$4-I26 -> 736 | R26: =I26+1080 -> 46542 | S26: =J26-$S$3 -> 360
B27: Instruções Manutenção Normativas e Gerenciais | C27: IM-ENG-028 | D27: Procedimento para alteração de set points parâmetros e ordem de ajustes | E27: Procedure for changing set points, parameters and order of adjustments | F27: ENGENHARIA CONFIABILIDADE E PERFORMANCE | G27: X | H27: X | I27: 45202 | J27: =I27+1096 -> 46298 | K27: Publicado | L27: =IF(N27="","",IF(N27>1095,"Vencido",IF(N27>910,"Alerta",IF(N27>820,"Alerta",IF(N27>730,"Alerta",IF(N27>=0,"Em dia","Vencido")))))) -> Alerta | N27: =$N$4-I27 -> 996 | S27: =J27-$S$3 -> 100
B28: Instruções Manutenção Mecânica | C28: IM-ENG-030 | D28: Dispositivos de Içamento | E28: Procedures for the use of lifting accessories | F28: ENGENHARIA MECÂNICA | G28: X | I28: 45202 | J28: =I28+1096 -> 46298 | K28: Publicado | L28: =IF(N28="","",IF(N28>1095,"Vencido",IF(N28>910,"Alerta",IF(N28>820,"Alerta",IF(N28>730,"Alerta",IF(N28>=0,"Em dia","Vencido")))))) -> Alerta | N28: =$N$4-I28 -> 996 | S28: =J28-$S$3 -> 100
B29: Instruções Manutenção Elétrica | C29: IM-ENG-031 | D29: Ensaios em Alto Potencial | E29: Procedures to perform high potencial tests | F29: ENGENHARIA ELÉTRICA | I29: - | K29: Cancelada | N29: =$N$4-I29 -> #VALUE!
B30: Instruções Manutenção Mecânica | C30: IM-ENG-032 | D30: Ensaios com Ultra-Som | E30: Procedures for Ultrasoud tests | F30: ENGENHARIA MECÂNICA | G30: X | I30: 45202 | J30: =I30+1096 -> 46298 | K30: Publicado | L30: =IF(N30="","",IF(N30>1095,"Vencido",IF(N30>910,"Alerta",IF(N30>820,"Alerta",IF(N30>730,"Alerta",IF(N30>=0,"Em dia","Vencido")))))) -> Alerta | N30: =$N$4-I30 -> 996 | S30: =J30-$S$3 -> 100
B31: Instruções Manutenção Elétrica | C31: IM-ENG-033 | D31: Ensaio de Corona Visual em Enrolamentos Estatóricos | E31: Visual Corona Testing on Stator Windings | F31: ENGENHARIA ELÉTRICA | G31: X | H31: x | I31: 46107 | J31: =I31+1096 -> 47203 | K31: Publicado | L31: =IF(N31="","",IF(N31>1095,"Vencido",IF(N31>910,"Alerta",IF(N31>820,"Aviso",IF(N31>730,"Comunicado",IF(N31>=0,"Em dia","Vencido")))))) -> Em dia | N31: =$N$4-I31 -> 91 | R31: =I31+1080 -> 47187 | S31: =J31-$S$3 -> 1005
B32: Instruções Manutenção Elétrica | C32: IM-ENG-034 | D32: Ensaios de Rendimento em Geradores Síncronos | E32: Performance tests on synchronous generators | F32: ENGENHARIA ELÉTRICA | G32: X | H32: X | I32: 45202 | J32: =I32+1096 -> 46298 | K32: Publicado | L32: =IF(N32="","",IF(N32>1095,"Vencido",IF(N32>910,"Alerta",IF(N32>820,"Alerta",IF(N32>730,"Alerta",IF(N32>=0,"Em dia","Vencido")))))) -> Alerta | N32: =$N$4-I32 -> 996 | S32: =J32-$S$3 -> 100
B33: Instruções Manutenção Elétrica | C33: IM-ENG-035 | D33: Ensaios de fator de potência em hidrogerador | E33: Power Factor Test in Hydro Generators | F33: ENGENHARIA ELÉTRICA | G33: X | I33: 45274 | J33: =I33+1096 -> 46370 | K33: Publicado | L33: =IF(N33="","",IF(N33>1095,"Vencido",IF(N33>910,"Alerta",IF(N33>820,"Alerta",IF(N33>730,"Alerta",IF(N33>=0,"Em dia","Vencido")))))) -> Alerta | N33: =$N$4-I33 -> 924 | S33: =J33-$S$3 -> 172
B34: Instruções Manutenção Elétrica | C34: IM-ENG-036 | D34: Ensaios e Verificações em Disjuntores | E34: Maintenance tests on H. V. circuit breaker | F34: ENGENHARIA ELÉTRICA | G34: X | I34: 45538 | J34: =I34+1096 -> 46634 | K34: Publicado | L34: =IF(N34="","",IF(N34>1095,"Vencido",IF(N34>910,"Alerta",IF(N34>820,"Aviso",IF(N34>730,"Comunicado",IF(N34>=0,"Em dia","Vencido")))))) -> Em dia | N34: =$N$4-I34 -> 660 | R34: =I34+1080 -> 46618 | S34: =J34-$S$3 -> 436
B35: Instruções Manutenção Elétrica | C35: IM-ENG-037 | D35: Pequenos reparos em geradores hidráulicos | E35: Minor repairs on hydraulic generators | F35: ENGENHARIA ELÉTRICA | G35: X | H35: X | I35: 45839 | J35: =I35+1096 -> 46935 | K35: Publicado | L35: =IF(N35="","",IF(N35>1095,"Vencido",IF(N35>910,"Alerta",IF(N35>820,"Aviso",IF(N35>730,"Comunicado",IF(N35>=0,"Em dia","Vencido")))))) -> Em dia | N35: =$N$4-I35 -> 359 | S35: =J35-$S$3 -> 737
B36: Instruções Manutenção Normativas e Gerenciais | C36: IM-ENG-038.1 | D36: Diagramas de padrões técnicos | E36: Diagrams of technical standard system | F36: ENGENHARIA CONFIABILIDADE E PERFORMANCE | G36: X | H36: X | I36: 45595 | J36: =I36+1096 -> 46691 | K36: Publicado | L36: =IF(N36="","",IF(N36>1095,"Vencido",IF(N36>910,"Alerta",IF(N36>820,"Aviso",IF(N36>730,"Comunicado",IF(N36>=0,"Em dia","Vencido")))))) -> Em dia | N36: =$N$4-I36 -> 603 | S36: =J36-$S$3 -> 493
B37: Instruções Manutenção Normativas e Gerenciais | C37: IM-ENG-038.2 | D37: Princípios e regras para elaboração de padrões técnicos | E37: Principles and rules for developing technical standards | F37: ENGENHARIA CONFIABILIDADE E PERFORMANCE | G37: X | H37: X | I37: 45595 | J37: =I37+1096 -> 46691 | K37: Publicado | L37: =IF(N37="","",IF(N37>1095,"Vencido",IF(N37>910,"Alerta",IF(N37>820,"Aviso",IF(N37>730,"Comunicado",IF(N37>=0,"Em dia","Vencido")))))) -> Em dia | N37: =$N$4-I37 -> 603 | S37: =J37-$S$3 -> 493
B38: Instruções Manutenção Normativas e Gerenciais | C38: IM-ENG-038.3 | D38: Padrões técnicos no nivel das UHEs | E38: Site level technical standards | F38: ENGENHARIA CONFIABILIDADE E PERFORMANCE | G38: X | H38: X | I38: 45595 | J38: =I38+1096 -> 46691 | K38: Publicado | L38: =IF(N38="","",IF(N38>1095,"Vencido",IF(N38>910,"Alerta",IF(N38>820,"Aviso",IF(N38>730,"Comunicado",IF(N38>=0,"Em dia","Vencido")))))) -> Em dia | N38: =$N$4-I38 -> 603 | S38: =J38-$S$3 -> 493
B39: Instruções Manutenção Normativas e Gerenciais | C39: IM-ENG-038.4 | D39: Procedimento Geração doc adm, relatórios e desenhos téc | E39: Generating technical reports and administrative documents | F39: ENGENHARIA CONFIABILIDADE E PERFORMANCE | G39: X | H39: X | I39: 45595 | J39: =I39+1096 -> 46691 | K39: Publicado | L39: =IF(N39="","",IF(N39>1095,"Vencido",IF(N39>910,"Alerta",IF(N39>820,"Aviso",IF(N39>730,"Comunicado",IF(N39>=0,"Em dia","Vencido")))))) -> Em dia | N39: =$N$4-I39 -> 603 | S39: =J39-$S$3 -> 493
B40: Instruções Manutenção Normativas e Gerenciais | C40: IM-ENG-038.5 | D40: Procedimento para arquivamento de documentos digitais | E40: Archiving Technical documents | F40: ENGENHARIA CONFIABILIDADE E PERFORMANCE | G40: X | H40: X | I40: 45595 | J40: =I40+1096 -> 46691 | K40: Publicado | L40: =IF(N40="","",IF(N40>1095,"Vencido",IF(N40>910,"Alerta",IF(N40>820,"Aviso",IF(N40>730,"Comunicado",IF(N40>=0,"Em dia","Vencido")))))) -> Em dia | N40: =$N$4-I40 -> 603 | S40: =J40-$S$3 -> 493
B41: Instruções Manutenção Elétrica | C41: IM-ENG-042 | D41: Manut Conexões Flex aparafusadas barram media tensão | E41: Maintenance of flexible power shunts installed in Medium Voltage | F41: ENGENHARIA ELÉTRICA | I41: - | K41: Cancelada | N41: =$N$4-I41 -> #VALUE!
...

Sheet GM
B2: GM - GUIAS DE MANUTENÇÃO (MAINTENANCE GUIDES)
H3: =COUNTIF(H4:H795,"X") -> 751 | I3: =COUNTIF(I4:I1413,"X") -> 698 | P3: =TODAY() -> 46198
B4: UHE/HPP | C4: UHE/HPP | D4: NUMERO / NUMBER | E4: DESCRIÇÃO | F4: DESCRIPTION | G4: Area | H4: Por. | I4: Ing. | J4: Data | K4: Data Vencimento | L4: Status | M4: Status validade | N4: Revisão /novo | O4: =TODAY() -> 46198 | P4: Dias que falta para vencer
B5: 2 | C5: CHV | D5: 0 | E5: GM-CHV-00_Atividades antes e depois da MPP | F5: GM-CHV-00_Activities before and after MPP | G5: ENGENHARIA | H5: X | J5: 45202 | K5: =J5+1096 -> 46298 | L5: Publicado | M5: =IF(O5="","",IF(O5>1095,"Vencido",IF(O5>910,"Alerta",IF(O5>820,"Alerta",IF(O5>730,"Alerta",IF(O5>=0,"Em dia","Vencido")))))) -> Alerta | O5: =$O$4-J5 -> 996 | P5: =K5-$P$3 -> 100 | Q5: =IF(OR(C5="ARN",C5="SDP"),MID(E5,4,7),MID(E5,4,6)) -> CHV-00
B6: 2 | C6: CHV | D6: 1 | E6: GM-CHV-01_Turbina e equipamentos auxiliares | F6: GM-CHV-01_Turbine and its Auxiliary Equipment | G6: ENGENHARIA MECÂNICA | H6: X | I6: X | J6: 44739 | K6: =J6+1096 -> 45835 | L6: Publicado | M6: =IF(O6="","",IF(O6>1095,"Vencido",IF(O6>910,"Alerta",IF(O6>820,"Alerta",IF(O6>730,"Alerta",IF(O6>=0,"Em dia","Vencido")))))) -> Vencido | O6: =$O$4-J6 -> 1459 | P6: =K6-$P$3 -> -363 | Q6: =IF(OR(C6="ARN",C6="SDP"),MID(E6,4,7),MID(E6,4,6)) -> CHV-01
B7: 2 | C7: CHV | D7: 2 | E7: GM-CHV-02_Gerador e Equipamentos Auxiliares - Parte Mecânica | F7: GM-CHV-02_Generator Mechanical Part and Its Auxiliary Equipment | G7: ENGENHARIA MECÂNICA | H7: X | I7: X | J7: 44739 | K7: =J7+1096 -> 45835 | L7: Publicado | M7: =IF(O7="","",IF(O7>1095,"Vencido",IF(O7>910,"Alerta",IF(O7>820,"Alerta",IF(O7>730,"Alerta",IF(O7>=0,"Em dia","Vencido")))))) -> Vencido | O7: =$O$4-J7 -> 1459 | P7: =K7-$P$3 -> -363 | Q7: =IF(OR(C7="ARN",C7="SDP"),MID(E7,4,7),MID(E7,4,6)) -> CHV-02
B8: 2 | C8: CHV | D8: 3 | E8: GM-CHV-03_Gerador-Parte elétrica | F8: GM-CHV-03_Generator-Electric parts | G8: ENGENHARIA ELÉTRICA | H8: X | I8: X | J8: 45506 | K8: =J8+1096 -> 46602 | L8: Publicado | M8: =IF(O8="","",IF(O8>1095,"Vencido",IF(O8>910,"Alerta",IF(O8>820,"Alerta",IF(O8>730,"Alerta",IF(O8>=0,"Em dia","Vencido")))))) -> Em dia | O8: =$O$4-J8 -> 692 | P8: =K8-$P$3 -> 404 | Q8: =IF(OR(C8="ARN",C8="SDP"),MID(E8,4,7),MID(E8,4,6)) -> CHV-03
B9: 2 | C9: CHV | D9: 4 | E9: GM-CHV-04_Sistemas Auxiliares da Unidade Geradora | F9: GM-CHV-04_Generating Unit Auxiliary Control System | G9: ENGENHARIA ELÉTRICA | H9: X | I9: X | J9: 46104 | K9: =J9+1096 -> 47200 | L9: Publicado | M9: =IF(O9="","",IF(O9>1095,"Vencido",IF(O9>910,"Alerta",IF(O9>820,"Alerta",IF(O9>730,"Alerta",IF(O9>=0,"Em dia","Vencido")))))) -> Em dia | O9: =$O$4-J9 -> 94 | P9: =K9-$P$3 -> 1002 | Q9: =IF(OR(C9="ARN",C9="SDP"),MID(E9,4,7),MID(E9,4,6)) -> CHV-04
B10: 2 | C10: CHV | D10: 5 | E10: GM-CHV-05_Barramento de Saída do Gerador e Seus Acessórios | F10: GM-CHV-05_Generator Output Buses and Its Accessories | G10: ENGENHARIA ELÉTRICA | H10: X | I10: X | J10: 46104 | K10: =J10+1096 -> 47200 | L10: Publicado | M10: =IF(O10="","",IF(O10>1095,"Vencido",IF(O10>910,"Alerta",IF(O10>820,"Alerta",IF(O10>730,"Alerta",IF(O10>=0,"Em dia","Vencido")))))) -> Em dia | O10: =$O$4-J10 -> 94 | P10: =K10-$P$3 -> 1002 | Q10: =IF(OR(C10="ARN",C10="SDP"),MID(E10,4,7),MID(E10,4,6)) -> CHV-05
B11: 2 | C11: CHV | D11: 6 | E11: GM-CHV-06_Transformador Elevador | F11: GM-CHV-06_Step-up Transformer | G11: ENGENHARIA ELÉTRICA | H11: X | I11: X | J11: 46104 | K11: =J11+1096 -> 47200 | L11: Publicado | M11: =IF(O11="","",IF(O11>1095,"Vencido",IF(O11>910,"Alerta",IF(O11>820,"Alerta",IF(O11>730,"Alerta",IF(O11>=0,"Em dia","Vencido")))))) -> Em dia | O11: =$O$4-J11 -> 94 | P11: =K11-$P$3 -> 1002 | Q11: =IF(OR(C11="ARN",C11="SDP"),MID(E11,4,7),MID(E11,4,6)) -> CHV-06
B12: 2 | C12: CHV | D12: 7 | E12: GM-CHV-07_Transformadores a Seco | F12: GM-CHV-07_Dry-type Transformer | G12: ENGENHARIA ELÉTRICA | H12: X | I12: X | J12: 45959 | K12: =J12+1096 -> 47055 | L12: Publicado | M12: =IF(O12="","",IF(O12>1095,"Vencido",IF(O12>910,"Alerta",IF(O12>820,"Alerta",IF(O12>730,"Alerta",IF(O12>=0,"Em dia","Vencido")))))) -> Em dia | O12: =$O$4-J12 -> 239 | P12: =K12-$P$3 -> 857 | Q12: =IF(OR(C12="ARN",C12="SDP"),MID(E12,4,7),MID(E12,4,6)) -> CHV-07
B13: 2 | C13: CHV | D13: 8 | E13: GM-CHV-08_Equipamentos de Alta Tensão | F13: GM-CHV-08_High Voltage Equipment | G13: ENGENHARIA ELÉTRICA | H13: X | I13: X | J13: 45645 | K13: =J13+1096 -> 46741 | L13: Publicado | M13: =IF(O13="","",IF(O13>1095,"Vencido",IF(O13>910,"Alerta",IF(O13>820,"Alerta",IF(O13>730,"Alerta",IF(O13>=0,"Em dia","Vencido")))))) -> Em dia | O13: =$O$4-J13 -> 553 | P13: =K13-$P$3 -> 543 | Q13: =IF(OR(C13="ARN",C13="SDP"),MID(E13,4,7),MID(E13,4,6)) -> CHV-08
B14: 2 | C14: CHV | D14: 9 | E14: GM-CHV-09_Painéis de Média Tensão | F14: GM-CHV-09_Medium Voltage Switch Cabinet | G14: ENGENHARIA ELÉTRICA | H14: X | I14: X | J14: 45959 | K14: =J14+1096 -> 47055 | L14: Publicado | M14: =IF(O14="","",IF(O14>1095,"Vencido",IF(O14>910,"Alerta",IF(O14>820,"Alerta",IF(O14>730,"Alerta",IF(O14>=0,"Em dia","Vencido")))))) -> Em dia | O14: =$O$4-J14 -> 239 | P14: =K14-$P$3 -> 857 | Q14: =IF(OR(C14="ARN",C14="SDP"),MID(E14,4,7),MID(E14,4,6)) -> CHV-09
B15: 2 | C15: CHV | D15: 10 | E15: GM-CHV-10_Painéis de Baixa Tensão | F15: GM-CHV-10_Low Voltage Switch Cabinet | G15: ENGENHARIA ELÉTRICA | H15: X | I15: X | J15: 45959 | K15: =J15+1096 -> 47055 | L15: Publicado | M15: =IF(O15="","",IF(O15>1095,"Vencido",IF(O15>910,"Alerta",IF(O15>820,"Alerta",IF(O15>730,"Alerta",IF(O15>=0,"Em dia","Vencido")))))) -> Em dia | O15: =$O$4-J15 -> 239 | P15: =K15-$P$3 -> 857 | Q15: =IF(OR(C15="ARN",C15="SDP"),MID(E15,4,7),MID(E15,4,6)) -> CHV-10
B16: 2 | C16: CHV | D16: 11 | E16: GM-CHV-11_Cabos de Potência até 35kV | F16: GM-CHV-11_Power Cable Up to 35kV | G16: ENGENHARIA ELÉTRICA | H16: X | I16: X | J16: 46104 | K16: =J16+1096 -> 47200 | L16: Publicado | M16: =IF(O16="","",IF(O16>1095,"Vencido",IF(O16>910,"Alerta",IF(O16>820,"Alerta",IF(O16>730,"Alerta",IF(O16>=0,"Em dia","Vencido")))))) -> Em dia | O16: =$O$4-J16 -> 94 | P16: =K16-$P$3 -> 1002 | Q16: =IF(OR(C16="ARN",C16="SDP"),MID(E16,4,7),MID(E16,4,6)) -> CHV-11
B17: 2 | C17: CHV | D17: 12 | E17: GM-CHV-12_Estação de Operacão - Computador | F17: GM-CHV-12_Operation Station - Computer | G17: ENGENHARIA ELÉTRICA | H17: X | I17: X | J17: 46104 | K17: =J17+1096 -> 47200 | L17: Publicado | M17: =IF(O17="","",IF(O17>1095,"Vencido",IF(O17>910,"Alerta",IF(O17>820,"Alerta",IF(O17>730,"Alerta",IF(O17>=0,"Em dia","Vencido")))))) -> Em dia | O17: =$O$4-J17 -> 94 | P17: =K17-$P$3 -> 1002 | Q17: =IF(OR(C17="ARN",C17="SDP"),MID(E17,4,7),MID(E17,4,6)) -> CHV-12
... B33: 2 | C33: CHV | D33: 29 | E33: GM-CHV-29_Grade | F33: GM-CHV-29_Trash Rack | G33: ENGENHARIA MECÂNICA | H33: X | I33: X | J33: 45202 | K33: =J33+1096 -> 46298 | L33: Publicado | M33: =IF(O33="","",IF(O33>1095,"Vencido",IF(O33>910,"Alerta",IF(O33>820,"Alerta",IF(O33>730,"Alerta",IF(O33>=0,"Em dia","Vencido")))))) -> Alerta | O33: =$O$4-J33 -> 996 | P33: =K33-$P$3 -> 100 | Q33: =IF(OR(C33="ARN",C33="SDP"),MID(E33,4,7),MID(E33,4,6)) -> CHV-29
B34: 2 | C34: CHV | D34: 40 | E34: GM-CHV-40_Sistema de iluminação e pontos de tomada | F34: GM-CHV-40_Lighting system and outlet points | G34: ENGENHARIA ELÉTRICA | H34: X | J34: 45202 | K34: =J34+1096 -> 46298 | L34: Publicado | M34: =IF(O34="","",IF(O34>1095,"Vencido",IF(O34>910,"Alerta",IF(O34>820,"Alerta",IF(O34>730,"Alerta",IF(O34>=0,"Em dia","Vencido")))))) -> Alerta | O34: =$O$4-J34 -> 996 | P34: =K34-$P$3 -> 100 | Q34: =IF(OR(C34="ARN",C34="SDP"),MID(E34,4,7),MID(E34,4,6)) -> CHV-40
B35: 2 | C35: CHV | D35: 41 | E35: GM-CHV-41_Sistema Proteção Descargas Atmosféricas (SPDA) | F35: GM-CHV-41_Lightining Protection system | G35: ENGENHARIA ELÉTRICA | H35: X | J35: 45202 | K35: =J35+1096 -> 46298 | L35: Publicado | M35: =IF(O35="","",IF(O35>1095,"Vencido",IF(O35>910,"Alerta",IF(O35>820,"Alerta",IF(O35>730,"Alerta",IF(O35>=0,"Em dia","Vencido")))))) -> Alerta | O35: =$O$4-J35 -> 996 | P35: =K35-$P$3 -> 100 | Q35: =IF(OR(C35="ARN",C35="SDP"),MID(E35,4,7),MID(E35,4,6)) -> CHV-41
B36: 2 | C36: CHV | D36: 51 | E36: GM-CHV-51_Transformadores auxiliares imersos em óleo | F36: GM-CHV-51_Oil-immersed Auxiliary Transformer | G36: ENGENHARIA ELÉTRICA | H36: X | I36: X | J36: 45959 | K36: =J36+1096 -> 47055 | L36: Publicado | M36: =IF(O36="","",IF(O36>1095,"Vencido",IF(O36>910,"Alerta",IF(O36>820,"Alerta",IF(O36>730,"Alerta",IF(O36>=0,"Em dia","Vencido")))))) -> Em dia | O36: =$O$4-J36 -> 239 | P36: =K36-$P$3 -> 857 | Q36: =IF(OR(C36="ARN",C36="SDP"),MID(E36,4,7),MID(E36,4,6)) -> CHV-51
B37: 2 | C37: CHV | D37: 59 | E37: GM-CHV-59_Sistema_CFTV | F37: GM-CHV-59_CCTV System | G37: ENGENHARIA ELÉTRICA | H37: X | I37: X | J37: 45462 | K37: =J37+1096 -> 46558 | L37: Publicado | M37: =IF(O37="","",IF(O37>1095,"Vencido",IF(O37>910,"Alerta",IF(O37>820,"Alerta",IF(O37>730,"Alerta",IF(O37>=0,"Em dia","Vencido")))))) -> Alerta | O37: =$O$4-J37 -> 736 | P37: =K37-$P$3 -> 360 | Q37: =IF(OR(C37="ARN",C37="SDP"),MID(E37,4,7),MID(E37,4,6)) -> CHV-59
B38: 2 | C38: CHV | D38: 60 | E38: GM-CHV-60_Sistema anti incêndio | F38: GM-CHV-60_Firefighting System | G38: ENGENHARIA MECÂNICA | H38: X | I38: X | J38: 44819 | K38: =J38+1096 -> 45915 | L38: Publicado | M38: =IF(O38="","",IF(O38>1095,"Vencido",IF(O38>910,"Alerta",IF(O38>820,"Alerta",IF(O38>730,"Alerta",IF(O38>=0,"Em dia","Vencido")))))) -> Vencido | O38: =$O$4-J38 -> 1379 | P38: =K38-$P$3 -> -283 | Q38: =IF(OR(C38="ARN",C38="SDP"),MID(E38,4,7),MID(E38,4,6)) -> CHV-60
B39: 2 | C39: CHV | D39: 61 | E39: GM-CHV-61_Comporta de vertedouro | F39: GM-CHV-61_Spillway Gate | G39: ENGENHARIA MECÂNICA | H39: X | I39: X | J39: 44926 | K39: =J39+1096 -> 46022 | L39: Publicado | M39: =IF(O39="","",IF(O39>1095,"Vencido",IF(O39>910,"Alerta",IF(O39>820,"Alerta",IF(O39>730,"Alerta",IF(O39>=0,"Em dia","Vencido")))))) -> Vencido | O39: =$O$4-J39 -> 1272 | P39: =K39-$P$3 -> -176 | Q39: =IF(OR(C39="ARN",C39="SDP"),MID(E39,4,7),MID(E39,4,6)) -> CHV-61
B40: 2 | C40: CHV | D40: 62 | E40: GM-CHV-62_Comporta de emergência | F40: GM-CHV-62_Emergency Gate | G40: ENGENHARIA MECÂNICA | H40: X | I40: X | J40: 44926 | K40: =J40+1096 -> 46022 | L40: Publicado | M40: =IF(O40="","",IF(O40>1095,"Vencido",IF(O40>910,"Alerta",IF(O40>820,"Alerta",IF(O40>730,"Alerta",IF(O40>=0,"Em dia","Vencido")))))) -> Vencido | O40: =$O$4-J40 -> 1272 | P40: =K40-$P$3 -> -176 | Q40: =IF(OR(C40="ARN",C40="SDP"),MID(E40,4,7),MID(E40,4,6)) -> CHV-62
B41: 2 | C41: CHV | D41: 63 | E41: GM-CHV-63_Ponte rolante jusante | F41: GM-CHV-63_Downstream Bridge Crane | G41: ENGENHARIA MECÂNICA | H41: X | I41: X | J41: 44838 | K41: =J41+1096 -> 45934 | L41: Publicado | M41: =IF(O41="","",IF(O41>1095,"Vencido",IF(O41>910,"Alerta",IF(O41>820,"Alerta",IF(O41>730,"Alerta",IF(O41>=0,"Em dia","Vencido")))))) -> Vencido | O41: =$O$4-J41 -> 1360 | P41: =K41-$P$3 -> -264 | Q41: =IF(OR(C41="ARN",C41="SDP"),MID(E41,4,7),MID(E41,4,6)) -> CHV-63
